[2024-05-31T15:13:28.025+0000] {taskinstance.py:1979} INFO - Dependencies all met for dep_context=non-requeueable deps ti=<TaskInstance: etl_csv_files.get_files_customer manual__2024-05-31T15:13:26.168724+00:00 [queued]>
[2024-05-31T15:13:28.031+0000] {taskinstance.py:1979} INFO - Dependencies all met for dep_context=requeueable deps ti=<TaskInstance: etl_csv_files.get_files_customer manual__2024-05-31T15:13:26.168724+00:00 [queued]>
[2024-05-31T15:13:28.031+0000] {taskinstance.py:2193} INFO - Starting attempt 1 of 1
[2024-05-31T15:13:28.048+0000] {taskinstance.py:2217} INFO - Executing <Task(_PythonDecoratedOperator): get_files_customer> on 2024-05-31 15:13:26.168724+00:00
[2024-05-31T15:13:28.052+0000] {standard_task_runner.py:60} INFO - Started process 406 to run task
[2024-05-31T15:13:28.056+0000] {standard_task_runner.py:87} INFO - Running: ['airflow', 'tasks', 'run', 'etl_csv_files', 'get_files_customer', 'manual__2024-05-31T15:13:26.168724+00:00', '--job-id', '16', '--raw', '--subdir', 'DAGS_FOLDER/etl_from_csv.py', '--cfg-path', '/tmp/tmpuvzabuac']
[2024-05-31T15:13:28.058+0000] {standard_task_runner.py:88} INFO - Job 16: Subtask get_files_customer
[2024-05-31T15:13:28.092+0000] {task_command.py:423} INFO - Running <TaskInstance: etl_csv_files.get_files_customer manual__2024-05-31T15:13:26.168724+00:00 [running]> on host 720c72730b57
[2024-05-31T15:13:28.139+0000] {taskinstance.py:2513} INFO - Exporting env vars: AIRFLOW_CTX_DAG_OWNER='airflow' AIRFLOW_CTX_DAG_ID='etl_csv_files' AIRFLOW_CTX_TASK_ID='get_files_customer' AIRFLOW_CTX_EXECUTION_DATE='2024-05-31T15:13:26.168724+00:00' AIRFLOW_CTX_TRY_NUMBER='1' AIRFLOW_CTX_DAG_RUN_ID='manual__2024-05-31T15:13:26.168724+00:00'
[2024-05-31T15:13:58.887+0000] {taskinstance.py:2731} ERROR - Task failed with exception
Traceback (most recent call last):
  File "/home/airflow/.local/lib/python3.8/site-packages/airflow/models/taskinstance.py", line 444, in _execute_task
    result = _execute_callable(context=context, **execute_callable_kwargs)
  File "/home/airflow/.local/lib/python3.8/site-packages/airflow/models/taskinstance.py", line 414, in _execute_callable
    return execute_callable(context=context, **execute_callable_kwargs)
  File "/home/airflow/.local/lib/python3.8/site-packages/airflow/decorators/base.py", line 241, in execute
    return_value = super().execute(context)
  File "/home/airflow/.local/lib/python3.8/site-packages/airflow/operators/python.py", line 200, in execute
    return_value = self.execute_callable()
  File "/home/airflow/.local/lib/python3.8/site-packages/airflow/operators/python.py", line 217, in execute_callable
    return self.python_callable(*self.op_args, **self.op_kwargs)
  File "/opt/airflow/dags/etl_from_csv.py", line 34, in get_files_customer
    df = read_from_gdrive(url,file_name)
  File "/opt/airflow/dags/etl_from_csv.py", line 25, in read_from_gdrive
    df = pd.read_csv(url)
  File "/home/airflow/.local/lib/python3.8/site-packages/pandas/io/parsers/readers.py", line 912, in read_csv
    return _read(filepath_or_buffer, kwds)
  File "/home/airflow/.local/lib/python3.8/site-packages/pandas/io/parsers/readers.py", line 577, in _read
    parser = TextFileReader(filepath_or_buffer, **kwds)
  File "/home/airflow/.local/lib/python3.8/site-packages/pandas/io/parsers/readers.py", line 1407, in __init__
    self._engine = self._make_engine(f, self.engine)
  File "/home/airflow/.local/lib/python3.8/site-packages/pandas/io/parsers/readers.py", line 1661, in _make_engine
    self.handles = get_handle(
  File "/home/airflow/.local/lib/python3.8/site-packages/pandas/io/common.py", line 716, in get_handle
    ioargs = _get_filepath_or_buffer(
  File "/home/airflow/.local/lib/python3.8/site-packages/pandas/io/common.py", line 368, in _get_filepath_or_buffer
    with urlopen(req_info) as req:
  File "/home/airflow/.local/lib/python3.8/site-packages/pandas/io/common.py", line 270, in urlopen
    return urllib.request.urlopen(*args, **kwargs)
  File "/usr/local/lib/python3.8/urllib/request.py", line 222, in urlopen
    return opener.open(url, data, timeout)
  File "/usr/local/lib/python3.8/urllib/request.py", line 531, in open
    response = meth(req, response)
  File "/usr/local/lib/python3.8/urllib/request.py", line 640, in http_response
    response = self.parent.error(
  File "/usr/local/lib/python3.8/urllib/request.py", line 563, in error
    result = self._call_chain(*args)
  File "/usr/local/lib/python3.8/urllib/request.py", line 502, in _call_chain
    result = func(*args)
  File "/usr/local/lib/python3.8/urllib/request.py", line 755, in http_error_302
    return self.parent.open(new, timeout=req.timeout)
  File "/usr/local/lib/python3.8/urllib/request.py", line 531, in open
    response = meth(req, response)
  File "/usr/local/lib/python3.8/urllib/request.py", line 640, in http_response
    response = self.parent.error(
  File "/usr/local/lib/python3.8/urllib/request.py", line 569, in error
    return self._call_chain(*args)
  File "/usr/local/lib/python3.8/urllib/request.py", line 502, in _call_chain
    result = func(*args)
  File "/usr/local/lib/python3.8/urllib/request.py", line 649, in http_error_default
    raise HTTPError(req.full_url, code, msg, hdrs, fp)
urllib.error.HTTPError: HTTP Error 500: Internal Server Error
[2024-05-31T15:13:58.930+0000] {taskinstance.py:1149} INFO - Marking task as FAILED. dag_id=etl_csv_files, task_id=get_files_customer, execution_date=20240531T151326, start_date=20240531T151328, end_date=20240531T151358
[2024-05-31T15:13:58.946+0000] {standard_task_runner.py:107} ERROR - Failed to execute job 16 for task get_files_customer (HTTP Error 500: Internal Server Error; 406)
[2024-05-31T15:13:58.976+0000] {local_task_job_runner.py:234} INFO - Task exited with return code 1
[2024-05-31T15:13:58.995+0000] {taskinstance.py:3312} INFO - 0 downstream tasks scheduled from follow-on schedule check
