[2024-05-31T14:47:23.561+0000] {taskinstance.py:1979} INFO - Dependencies all met for dep_context=non-requeueable deps ti=<TaskInstance: etl_csv_files.combine_files scheduled__2024-04-01T00:00:00+00:00 [queued]>
[2024-05-31T14:47:23.572+0000] {taskinstance.py:1979} INFO - Dependencies all met for dep_context=requeueable deps ti=<TaskInstance: etl_csv_files.combine_files scheduled__2024-04-01T00:00:00+00:00 [queued]>
[2024-05-31T14:47:23.573+0000] {taskinstance.py:2193} INFO - Starting attempt 1 of 1
[2024-05-31T14:47:23.590+0000] {taskinstance.py:2217} INFO - Executing <Task(_PythonDecoratedOperator): combine_files> on 2024-04-01 00:00:00+00:00
[2024-05-31T14:47:23.594+0000] {standard_task_runner.py:60} INFO - Started process 428 to run task
[2024-05-31T14:47:23.605+0000] {standard_task_runner.py:87} INFO - Running: ['airflow', 'tasks', 'run', 'etl_csv_files', 'combine_files', 'scheduled__2024-04-01T00:00:00+00:00', '--job-id', '42', '--raw', '--subdir', 'DAGS_FOLDER/testfile.py', '--cfg-path', '/tmp/tmpylmed70x']
[2024-05-31T14:47:23.609+0000] {standard_task_runner.py:88} INFO - Job 42: Subtask combine_files
[2024-05-31T14:47:23.678+0000] {task_command.py:423} INFO - Running <TaskInstance: etl_csv_files.combine_files scheduled__2024-04-01T00:00:00+00:00 [running]> on host 66ed76cf62da
[2024-05-31T14:47:23.956+0000] {taskinstance.py:2513} INFO - Exporting env vars: AIRFLOW_CTX_DAG_OWNER='airflow' AIRFLOW_CTX_DAG_ID='etl_csv_files' AIRFLOW_CTX_TASK_ID='combine_files' AIRFLOW_CTX_EXECUTION_DATE='2024-04-01T00:00:00+00:00' AIRFLOW_CTX_TRY_NUMBER='1' AIRFLOW_CTX_DAG_RUN_ID='scheduled__2024-04-01T00:00:00+00:00'
[2024-05-31T14:47:24.159+0000] {taskinstance.py:2731} ERROR - Task failed with exception
Traceback (most recent call last):
  File "/home/airflow/.local/lib/python3.8/site-packages/airflow/models/taskinstance.py", line 444, in _execute_task
    result = _execute_callable(context=context, **execute_callable_kwargs)
  File "/home/airflow/.local/lib/python3.8/site-packages/airflow/models/taskinstance.py", line 414, in _execute_callable
    return execute_callable(context=context, **execute_callable_kwargs)
  File "/home/airflow/.local/lib/python3.8/site-packages/airflow/decorators/base.py", line 241, in execute
    return_value = super().execute(context)
  File "/home/airflow/.local/lib/python3.8/site-packages/airflow/operators/python.py", line 200, in execute
    return_value = self.execute_callable()
  File "/home/airflow/.local/lib/python3.8/site-packages/airflow/operators/python.py", line 217, in execute_callable
    return self.python_callable(*self.op_args, **self.op_kwargs)
  File "/opt/airflow/dags/testfile.py", line 55, in combine_files
    df = df_customer.set_index('customer_id').join(df_purchase.set_index('customer_id'), how='outer').reset_index()
AttributeError: 'NoneType' object has no attribute 'set_index'
[2024-05-31T14:47:24.225+0000] {taskinstance.py:1149} INFO - Marking task as FAILED. dag_id=etl_csv_files, task_id=combine_files, execution_date=20240401T000000, start_date=20240531T144723, end_date=20240531T144724
[2024-05-31T14:47:24.280+0000] {standard_task_runner.py:107} ERROR - Failed to execute job 42 for task combine_files ('NoneType' object has no attribute 'set_index'; 428)
[2024-05-31T14:47:24.327+0000] {local_task_job_runner.py:234} INFO - Task exited with return code 1
[2024-05-31T14:47:24.364+0000] {taskinstance.py:3312} INFO - 0 downstream tasks scheduled from follow-on schedule check
[2024-05-31T15:06:08.201+0000] {taskinstance.py:1979} INFO - Dependencies all met for dep_context=non-requeueable deps ti=<TaskInstance: etl_csv_files.combine_files scheduled__2024-04-01T00:00:00+00:00 [queued]>
[2024-05-31T15:06:08.207+0000] {taskinstance.py:1979} INFO - Dependencies all met for dep_context=requeueable deps ti=<TaskInstance: etl_csv_files.combine_files scheduled__2024-04-01T00:00:00+00:00 [queued]>
[2024-05-31T15:06:08.208+0000] {taskinstance.py:2193} INFO - Starting attempt 1 of 1
[2024-05-31T15:06:08.216+0000] {taskinstance.py:2217} INFO - Executing <Task(_PythonDecoratedOperator): combine_files> on 2024-04-01 00:00:00+00:00
[2024-05-31T15:06:08.219+0000] {standard_task_runner.py:60} INFO - Started process 217 to run task
[2024-05-31T15:06:08.222+0000] {standard_task_runner.py:87} INFO - Running: ['airflow', 'tasks', 'run', 'etl_csv_files', 'combine_files', 'scheduled__2024-04-01T00:00:00+00:00', '--job-id', '8', '--raw', '--subdir', 'DAGS_FOLDER/etl_from_csv.py', '--cfg-path', '/tmp/tmpts76kw1d']
[2024-05-31T15:06:08.223+0000] {standard_task_runner.py:88} INFO - Job 8: Subtask combine_files
[2024-05-31T15:06:08.249+0000] {task_command.py:423} INFO - Running <TaskInstance: etl_csv_files.combine_files scheduled__2024-04-01T00:00:00+00:00 [running]> on host 720c72730b57
[2024-05-31T15:06:08.286+0000] {taskinstance.py:2513} INFO - Exporting env vars: AIRFLOW_CTX_DAG_OWNER='airflow' AIRFLOW_CTX_DAG_ID='etl_csv_files' AIRFLOW_CTX_TASK_ID='combine_files' AIRFLOW_CTX_EXECUTION_DATE='2024-04-01T00:00:00+00:00' AIRFLOW_CTX_TRY_NUMBER='1' AIRFLOW_CTX_DAG_RUN_ID='scheduled__2024-04-01T00:00:00+00:00'
[2024-05-31T15:06:08.297+0000] {taskinstance.py:2731} ERROR - Task failed with exception
Traceback (most recent call last):
  File "/home/airflow/.local/lib/python3.8/site-packages/airflow/models/taskinstance.py", line 444, in _execute_task
    result = _execute_callable(context=context, **execute_callable_kwargs)
  File "/home/airflow/.local/lib/python3.8/site-packages/airflow/models/taskinstance.py", line 414, in _execute_callable
    return execute_callable(context=context, **execute_callable_kwargs)
  File "/home/airflow/.local/lib/python3.8/site-packages/airflow/decorators/base.py", line 241, in execute
    return_value = super().execute(context)
  File "/home/airflow/.local/lib/python3.8/site-packages/airflow/operators/python.py", line 200, in execute
    return_value = self.execute_callable()
  File "/home/airflow/.local/lib/python3.8/site-packages/airflow/operators/python.py", line 217, in execute_callable
    return self.python_callable(*self.op_args, **self.op_kwargs)
  File "/opt/airflow/dags/etl_from_csv.py", line 57, in combine_files
    df = df_customer.set_index('customer_id').join(df_purchase.set_index('customer_id'), how='outer').reset_index()
  File "/home/airflow/.local/lib/python3.8/site-packages/pandas/core/frame.py", line 9729, in join
    return self._join_compat(
  File "/home/airflow/.local/lib/python3.8/site-packages/pandas/core/frame.py", line 9768, in _join_compat
    return merge(
  File "/home/airflow/.local/lib/python3.8/site-packages/pandas/core/reshape/merge.py", line 162, in merge
    return op.get_result(copy=copy)
  File "/home/airflow/.local/lib/python3.8/site-packages/pandas/core/reshape/merge.py", line 811, in get_result
    result = self._reindex_and_concat(
  File "/home/airflow/.local/lib/python3.8/site-packages/pandas/core/reshape/merge.py", line 763, in _reindex_and_concat
    llabels, rlabels = _items_overlap_with_suffix(
  File "/home/airflow/.local/lib/python3.8/site-packages/pandas/core/reshape/merge.py", line 2604, in _items_overlap_with_suffix
    raise ValueError(f"columns overlap but no suffix specified: {to_rename}")
ValueError: columns overlap but no suffix specified: Index(['page_views', 'time_spent'], dtype='object')
[2024-05-31T15:06:08.305+0000] {taskinstance.py:1149} INFO - Marking task as FAILED. dag_id=etl_csv_files, task_id=combine_files, execution_date=20240401T000000, start_date=20240531T150608, end_date=20240531T150608
[2024-05-31T15:06:08.311+0000] {standard_task_runner.py:107} ERROR - Failed to execute job 8 for task combine_files (columns overlap but no suffix specified: Index(['page_views', 'time_spent'], dtype='object'); 217)
[2024-05-31T15:06:08.320+0000] {local_task_job_runner.py:234} INFO - Task exited with return code 1
[2024-05-31T15:06:08.331+0000] {taskinstance.py:3312} INFO - 0 downstream tasks scheduled from follow-on schedule check
