[2024-05-30T10:01:46.067+0000] {taskinstance.py:1979} INFO - Dependencies all met for dep_context=non-requeueable deps ti=<TaskInstance: etl_csv_files.insert_to_db scheduled__2024-04-10T08:00:00+00:00 [queued]>
[2024-05-30T10:01:46.078+0000] {taskinstance.py:1979} INFO - Dependencies all met for dep_context=requeueable deps ti=<TaskInstance: etl_csv_files.insert_to_db scheduled__2024-04-10T08:00:00+00:00 [queued]>
[2024-05-30T10:01:46.079+0000] {taskinstance.py:2193} INFO - Starting attempt 1 of 1
[2024-05-30T10:01:46.090+0000] {taskinstance.py:2217} INFO - Executing <Task(_PythonDecoratedOperator): insert_to_db> on 2024-04-10 08:00:00+00:00
[2024-05-30T10:01:46.095+0000] {standard_task_runner.py:60} INFO - Started process 1181 to run task
[2024-05-30T10:01:46.099+0000] {standard_task_runner.py:87} INFO - Running: ['airflow', 'tasks', 'run', 'etl_csv_files', 'insert_to_db', 'scheduled__2024-04-10T08:00:00+00:00', '--job-id', '150', '--raw', '--subdir', 'DAGS_FOLDER/testfile.py', '--cfg-path', '/tmp/tmpei6fw_2j']
[2024-05-30T10:01:46.102+0000] {standard_task_runner.py:88} INFO - Job 150: Subtask insert_to_db
[2024-05-30T10:01:46.181+0000] {task_command.py:423} INFO - Running <TaskInstance: etl_csv_files.insert_to_db scheduled__2024-04-10T08:00:00+00:00 [running]> on host 9daf870c1958
[2024-05-30T10:01:46.279+0000] {taskinstance.py:2513} INFO - Exporting env vars: AIRFLOW_CTX_DAG_OWNER='airflow' AIRFLOW_CTX_DAG_ID='etl_csv_files' AIRFLOW_CTX_TASK_ID='insert_to_db' AIRFLOW_CTX_EXECUTION_DATE='2024-04-10T08:00:00+00:00' AIRFLOW_CTX_TRY_NUMBER='1' AIRFLOW_CTX_DAG_RUN_ID='scheduled__2024-04-10T08:00:00+00:00'
[2024-05-30T10:01:46.292+0000] {taskinstance.py:2731} ERROR - Task failed with exception
Traceback (most recent call last):
  File "/home/airflow/.local/lib/python3.8/site-packages/airflow/models/taskinstance.py", line 444, in _execute_task
    result = _execute_callable(context=context, **execute_callable_kwargs)
  File "/home/airflow/.local/lib/python3.8/site-packages/airflow/models/taskinstance.py", line 414, in _execute_callable
    return execute_callable(context=context, **execute_callable_kwargs)
  File "/home/airflow/.local/lib/python3.8/site-packages/airflow/decorators/base.py", line 241, in execute
    return_value = super().execute(context)
  File "/home/airflow/.local/lib/python3.8/site-packages/airflow/operators/python.py", line 200, in execute
    return_value = self.execute_callable()
  File "/home/airflow/.local/lib/python3.8/site-packages/airflow/operators/python.py", line 217, in execute_callable
    return self.python_callable(*self.op_args, **self.op_kwargs)
  File "/opt/airflow/dags/testfile.py", line 63, in insert_to_db
    host = Variable.get('host_postgres_db')
  File "/home/airflow/.local/lib/python3.8/site-packages/airflow/models/variable.py", line 143, in get
    raise KeyError(f"Variable {key} does not exist")
KeyError: 'Variable host_postgres_db does not exist'
[2024-05-30T10:01:46.306+0000] {taskinstance.py:1149} INFO - Marking task as FAILED. dag_id=etl_csv_files, task_id=insert_to_db, execution_date=20240410T080000, start_date=20240530T100146, end_date=20240530T100146
[2024-05-30T10:01:46.317+0000] {standard_task_runner.py:107} ERROR - Failed to execute job 150 for task insert_to_db ('Variable host_postgres_db does not exist'; 1181)
[2024-05-30T10:01:46.362+0000] {local_task_job_runner.py:234} INFO - Task exited with return code 1
[2024-05-30T10:01:46.385+0000] {taskinstance.py:3312} INFO - 0 downstream tasks scheduled from follow-on schedule check
