[2024-05-30T10:00:39.793+0000] {taskinstance.py:1979} INFO - Dependencies all met for dep_context=non-requeueable deps ti=<TaskInstance: etl_csv_files.combine_files scheduled__2024-03-13T08:00:00+00:00 [queued]>
[2024-05-30T10:00:39.878+0000] {taskinstance.py:1979} INFO - Dependencies all met for dep_context=requeueable deps ti=<TaskInstance: etl_csv_files.combine_files scheduled__2024-03-13T08:00:00+00:00 [queued]>
[2024-05-30T10:00:39.884+0000] {taskinstance.py:2193} INFO - Starting attempt 1 of 1
[2024-05-30T10:00:40.135+0000] {taskinstance.py:2217} INFO - Executing <Task(_PythonDecoratedOperator): combine_files> on 2024-03-13 08:00:00+00:00
[2024-05-30T10:00:40.246+0000] {standard_task_runner.py:60} INFO - Started process 746 to run task
[2024-05-30T10:00:40.256+0000] {standard_task_runner.py:87} INFO - Running: ['airflow', 'tasks', 'run', 'etl_csv_files', 'combine_files', 'scheduled__2024-03-13T08:00:00+00:00', '--job-id', '57', '--raw', '--subdir', 'DAGS_FOLDER/testfile.py', '--cfg-path', '/tmp/tmp3ig8oxic']
[2024-05-30T10:00:40.275+0000] {standard_task_runner.py:88} INFO - Job 57: Subtask combine_files
[2024-05-30T10:00:41.087+0000] {task_command.py:423} INFO - Running <TaskInstance: etl_csv_files.combine_files scheduled__2024-03-13T08:00:00+00:00 [running]> on host 9daf870c1958
[2024-05-30T10:00:41.734+0000] {taskinstance.py:2513} INFO - Exporting env vars: AIRFLOW_CTX_DAG_OWNER='airflow' AIRFLOW_CTX_DAG_ID='etl_csv_files' AIRFLOW_CTX_TASK_ID='combine_files' AIRFLOW_CTX_EXECUTION_DATE='2024-03-13T08:00:00+00:00' AIRFLOW_CTX_TRY_NUMBER='1' AIRFLOW_CTX_DAG_RUN_ID='scheduled__2024-03-13T08:00:00+00:00'
[2024-05-30T10:00:41.897+0000] {taskinstance.py:2731} ERROR - Task failed with exception
Traceback (most recent call last):
  File "/home/airflow/.local/lib/python3.8/site-packages/airflow/models/taskinstance.py", line 444, in _execute_task
    result = _execute_callable(context=context, **execute_callable_kwargs)
  File "/home/airflow/.local/lib/python3.8/site-packages/airflow/models/taskinstance.py", line 414, in _execute_callable
    return execute_callable(context=context, **execute_callable_kwargs)
  File "/home/airflow/.local/lib/python3.8/site-packages/airflow/decorators/base.py", line 241, in execute
    return_value = super().execute(context)
  File "/home/airflow/.local/lib/python3.8/site-packages/airflow/operators/python.py", line 200, in execute
    return_value = self.execute_callable()
  File "/home/airflow/.local/lib/python3.8/site-packages/airflow/operators/python.py", line 217, in execute_callable
    return self.python_callable(*self.op_args, **self.op_kwargs)
  File "/opt/airflow/dags/testfile.py", line 55, in combine_files
    df = df_customer.set_index('customer_id').join(df_purchase.set_index('customer_id'), how='outer').reset_index()
AttributeError: 'NoneType' object has no attribute 'set_index'
[2024-05-30T10:00:41.931+0000] {taskinstance.py:1149} INFO - Marking task as FAILED. dag_id=etl_csv_files, task_id=combine_files, execution_date=20240313T080000, start_date=20240530T100039, end_date=20240530T100041
[2024-05-30T10:00:41.994+0000] {standard_task_runner.py:107} ERROR - Failed to execute job 57 for task combine_files ('NoneType' object has no attribute 'set_index'; 746)
[2024-05-30T10:00:42.081+0000] {local_task_job_runner.py:234} INFO - Task exited with return code 1
[2024-05-30T10:00:42.207+0000] {taskinstance.py:3312} INFO - 0 downstream tasks scheduled from follow-on schedule check
[2024-05-31T14:47:16.282+0000] {taskinstance.py:1979} INFO - Dependencies all met for dep_context=non-requeueable deps ti=<TaskInstance: etl_csv_files.combine_files scheduled__2024-03-13T08:00:00+00:00 [queued]>
[2024-05-31T14:47:16.389+0000] {taskinstance.py:1979} INFO - Dependencies all met for dep_context=requeueable deps ti=<TaskInstance: etl_csv_files.combine_files scheduled__2024-03-13T08:00:00+00:00 [queued]>
[2024-05-31T14:47:16.391+0000] {taskinstance.py:2193} INFO - Starting attempt 1 of 1
[2024-05-31T14:47:16.669+0000] {taskinstance.py:2217} INFO - Executing <Task(_PythonDecoratedOperator): combine_files> on 2024-03-13 08:00:00+00:00
[2024-05-31T14:47:16.874+0000] {standard_task_runner.py:87} INFO - Running: ['airflow', 'tasks', 'run', 'etl_csv_files', 'combine_files', 'scheduled__2024-03-13T08:00:00+00:00', '--job-id', '22', '--raw', '--subdir', 'DAGS_FOLDER/etl_from_csv.py', '--cfg-path', '/tmp/tmpmyytfujy']
[2024-05-31T14:47:16.827+0000] {standard_task_runner.py:60} INFO - Started process 396 to run task
[2024-05-31T14:47:16.921+0000] {standard_task_runner.py:88} INFO - Job 22: Subtask combine_files
[2024-05-31T14:47:17.450+0000] {task_command.py:423} INFO - Running <TaskInstance: etl_csv_files.combine_files scheduled__2024-03-13T08:00:00+00:00 [running]> on host 66ed76cf62da
[2024-05-31T14:47:17.918+0000] {taskinstance.py:2513} INFO - Exporting env vars: AIRFLOW_CTX_DAG_OWNER='airflow' AIRFLOW_CTX_DAG_ID='etl_csv_files' AIRFLOW_CTX_TASK_ID='combine_files' AIRFLOW_CTX_EXECUTION_DATE='2024-03-13T08:00:00+00:00' AIRFLOW_CTX_TRY_NUMBER='1' AIRFLOW_CTX_DAG_RUN_ID='scheduled__2024-03-13T08:00:00+00:00'
[2024-05-31T14:47:17.927+0000] {taskinstance.py:2731} ERROR - Task failed with exception
Traceback (most recent call last):
  File "/home/airflow/.local/lib/python3.8/site-packages/airflow/models/taskinstance.py", line 444, in _execute_task
    result = _execute_callable(context=context, **execute_callable_kwargs)
  File "/home/airflow/.local/lib/python3.8/site-packages/airflow/models/taskinstance.py", line 414, in _execute_callable
    return execute_callable(context=context, **execute_callable_kwargs)
  File "/home/airflow/.local/lib/python3.8/site-packages/airflow/decorators/base.py", line 241, in execute
    return_value = super().execute(context)
  File "/home/airflow/.local/lib/python3.8/site-packages/airflow/operators/python.py", line 200, in execute
    return_value = self.execute_callable()
  File "/home/airflow/.local/lib/python3.8/site-packages/airflow/operators/python.py", line 217, in execute_callable
    return self.python_callable(*self.op_args, **self.op_kwargs)
  File "/opt/airflow/dags/etl_from_csv.py", line 53, in combine_files
    df_customer = pd.read_csv(f'/opt/airflow/data/{list(files.keys())[0]}')
  File "/home/airflow/.local/lib/python3.8/site-packages/pandas/io/parsers/readers.py", line 912, in read_csv
    return _read(filepath_or_buffer, kwds)
  File "/home/airflow/.local/lib/python3.8/site-packages/pandas/io/parsers/readers.py", line 577, in _read
    parser = TextFileReader(filepath_or_buffer, **kwds)
  File "/home/airflow/.local/lib/python3.8/site-packages/pandas/io/parsers/readers.py", line 1407, in __init__
    self._engine = self._make_engine(f, self.engine)
  File "/home/airflow/.local/lib/python3.8/site-packages/pandas/io/parsers/readers.py", line 1661, in _make_engine
    self.handles = get_handle(
  File "/home/airflow/.local/lib/python3.8/site-packages/pandas/io/common.py", line 859, in get_handle
    handle = open(
FileNotFoundError: [Errno 2] No such file or directory: '/opt/airflow/data/customer_interactions'
[2024-05-31T14:47:17.959+0000] {taskinstance.py:1149} INFO - Marking task as FAILED. dag_id=etl_csv_files, task_id=combine_files, execution_date=20240313T080000, start_date=20240531T144716, end_date=20240531T144717
[2024-05-31T14:47:18.008+0000] {standard_task_runner.py:107} ERROR - Failed to execute job 22 for task combine_files ([Errno 2] No such file or directory: '/opt/airflow/data/customer_interactions'; 396)
[2024-05-31T14:47:18.094+0000] {local_task_job_runner.py:234} INFO - Task exited with return code 1
[2024-05-31T14:47:18.240+0000] {taskinstance.py:3312} INFO - 0 downstream tasks scheduled from follow-on schedule check
